Workbook

Sheet Cover
B2: Makita Corporation (6586 JP): initiation model
B3: By James Pieter Djibu, BSc Economics, Nagoya University, Class of 2028 (jamespieter16@gmail.com)
B4: Student research project, not investment advice. IFRS, JPY m, FY ends 31 March.
B6: Scenario | C6: =Assumptions!E4 -> Base
B7: Rating | C7: =DCF!$D$62 -> HOLD
B8: 12-month target price (JPY) | C8: =DCF!$D$58 -> 5850
B9: Current price (JPY) | C9: =Assumptions!$D$85 -> 5253
B10: Upside / (downside) | C10: =DCF!$D$60 -> 0.11364934
B11: DCF value, Gordon (JPY) | C11: =DCF!$D$41 -> 5487.7916
B12: DCF value, exit multiple (JPY) | C12: =DCF!$D$50 -> 5561.0671
B13: WACC | C13: =Assumptions!$D$101 -> 0.088373867
B14: Cost of equity | C14: =Assumptions!$D$96 -> 0.089380336
B15: Model checks | C15: =Checks!$C$25 -> ALL CHECKS PASS
B18: How to use: change Assumptions!D4 (1 Base, 2 Bull, 3 Bear). Everything recalculates.
B19: Colour code: blue = input or historical fact; black = formula; tinted = key output.
B20: Sheets: Assumptions > Drivers (regional revenue x FX) > IS > BS > CF > DCF > Comps > Sensitivity > Football > Checks.
B21: Sources: Makita earnings releases and audited statements; yfinance; MoF JGB; Damodaran. See SOURCES.md.
B22: Built by src/build_model.py and recalculated in LibreOffice; values are cached so the file opens with results.

Sheet Assumptions
A1: Assumptions
A2: Every forecast driver lives here. Change the scenario in D4. Blue = input.
A4: Scenario switch: 1 = Base, 2 = Bull, 3 = Bear | D4: 1 | E4: =CHOOSE($D$4,"Base","Bull","Bear") -> Base
A6: Time-series drivers (live row = CHOOSE on scenario) | C6: FY2022A | D6: FY2023A | E6: FY2024A | F6: FY2025A | G6: FY2026A | H6: FY2027E | I6: FY2028E | J6: FY2029E | K6: FY2030E | L6: FY2031E | M6: Source / note
A7: Local-currency growth: Europe (live) | B7: % | H7: =CHOOSE(Scenario,H8,H9,H10) -> 0 | I7: =CHOOSE(Scenario,I8,I9,I10) -> 0.025 | J7: =CHOOSE(Scenario,J8,J9,J10) -> 0.03 | K7: =CHOOSE(Scenario,K8,K9,K10) -> 0.03 | L7: =CHOOSE(Scenario,L8,L9,L10) -> 0.03 | M7: Implied LC growth FY2026 -1.5%, 1Q FY2027 -1.8% (Drivers sheet; 1Q: +11.2% in JPY vs EUR +13.2%). Base: flat FY27, then cordless/OPE-led recovery to ~3%
A8: Base | H8: 0 | I8: 0.025 | J8: 0.03 | K8: 0.03 | L8: 0.03
A9: Bull | H9: 0.02 | I9: 0.045 | J9: 0.05 | K9: 0.05 | L9: 0.04
A10: Bear | H10: -0.03 | I10: -0.005 | J10: 0.015 | K10: 0.02 | L10: 0.02
A11: Local-currency growth: Japan (live) | B11: % | H11: =CHOOSE(Scenario,H12,H13,H14) -> 0.025 | I11: =CHOOSE(Scenario,I12,I13,I14) -> 0.02 | J11: =CHOOSE(Scenario,J12,J13,J14) -> 0.02 | K11: =CHOOSE(Scenario,K12,K13,K14) -> 0.02 | L11: =CHOOSE(Scenario,L12,L13,L14) -> 0.015 | M11: FY2026 +3.9%, 1Q FY2027 +4.1%; housing starts falling. Base fades to ~2%
A12: Base | H12: 0.025 | I12: 0.02 | J12: 0.02 | K12: 0.02 | L12: 0.015
A13: Bull | H13: 0.04 | I13: 0.035 | J13: 0.03 | K13: 0.03 | L13: 0.025
A14: Bear | H14: 0 | I14: 0 | J14: 0.01 | K14: 0.01 | L14: 0.01
A15: Local-currency growth: North America (live) | B15: % | H15: =CHOOSE(Scenario,H16,H17,H18) -> 0.03 | I15: =CHOOSE(Scenario,I16,I17,I18) -> 0.03 | J15: =CHOOSE(Scenario,J16,J17,J18) -> 0.03 | K15: =CHOOSE(Scenario,K16,K17,K18) -> 0.03 | L15: =CHOOSE(Scenario,L16,L17,L18) -> 0.03 | M15: FY2026 LC -5%, 1Q FY2027 LC about +7% after tariff disruption. Base 3%: share stable vs TTI/DeWalt
A16: Base | H16: 0.03 | I16: 0.03 | J16: 0.03 | K16: 0.03 | L16: 0.03
A17: Bull | H17: 0.06 | I17: 0.06 | J17: 0.06 | K17: 0.05 | L17: 0.04
A18: Bear | H18: -0.03 | I18: 0 | J18: 0.01 | K18: 0.02 | L18: 0.02
A19: Local-currency growth: Rest of world (live) | B19: % | H19: =CHOOSE(Scenario,H20,H21,H22) -> 0.02 | I19: =CHOOSE(Scenario,I20,I21,I22) -> 0.035 | J19: =CHOOSE(Scenario,J20,J21,J22) -> 0.04 | K19: =CHOOSE(Scenario,K20,K21,K22) -> 0.04 | L19: =CHOOSE(Scenario,L20,L21,L22) -> 0.035 | M19: Asia, Latin America, Oceania, Middle East & Africa; USD used as FX proxy. FY2026 implied LC +5%, 1Q FY2027 ~0%
A20: Base | H20: 0.02 | I20: 0.035 | J20: 0.04 | K20: 0.04 | L20: 0.035
A21: Bull | H21: 0.04 | I21: 0.05 | J21: 0.055 | K21: 0.055 | L21: 0.05
A22: Bear | H22: -0.02 | I22: 0.01 | J22: 0.02 | K22: 0.025 | L22: 0.025
A23: USD/JPY (fiscal-year average) (live) | B23: JPY | H23: =CHOOSE(Scenario,H24,H25,H26) -> 158.26 | I23: =CHOOSE(Scenario,I24,I25,I26) -> 157.82 | J23: =CHOOSE(Scenario,J24,J25,J26) -> 157.82 | K23: =CHOOSE(Scenario,K24,K25,K26) -> 157.82 | L23: =CHOOSE(Scenario,L24,L25,L26) -> 157.82 | M23: Base: 1Q actual 159.57 blended with spot 157.82 (29 Oct 2026) for 3 quarters, then spot held (random walk). Bull: yen -5%. Bear: yen +10%
A24: Base | H24: 158.26 | I24: 157.82 | J24: 157.82 | K24: 157.82 | L24: 157.82
A25: Bull | H25: 158.26 | I25: 165.71 | J25: 165.71 | K25: 165.71 | L25: 165.71
A26: Bear | H26: 154.31 | I26: 142.04 | J26: 142.04 | K26: 142.04 | L26: 142.04
A27: EUR/JPY (fiscal-year average) (live) | B27: JPY | H27: =CHOOSE(Scenario,H28,H29,H30) -> 178.38 | I27: =CHOOSE(Scenario,I28,I29,I30) -> 176.03 | J27: =CHOOSE(Scenario,J28,J29,J30) -> 176.03 | K27: =CHOOSE(Scenario,K28,K29,K30) -> 176.03 | L27: =CHOOSE(Scenario,L28,L29,L30) -> 176.03 | M27: Base: 1Q actual 185.41 blended with spot 176.03 for 3 quarters, then spot held. Bull: yen -5%. Bear: yen +10%
A28: Base | H28: 178.38 | I28: 176.03 | J28: 176.03 | K28: 176.03 | L28: 176.03
A29: Bull | H29: 178.38 | I29: 184.83 | J29: 184.83 | K29: 184.83 | L29: 184.83
A30: Bear | H30: 174.08 | I30: 158.43 | J30: 158.43 | K30: 158.43 | L30: 158.43
A31: Gross margin (live) | B31: % | H31: =CHOOSE(Scenario,H32,H33,H34) -> 0.37 | I31: =CHOOSE(Scenario,I32,I33,I34) -> 0.365 | J31: =CHOOSE(Scenario,J32,J33,J34) -> 0.365 | K31: =CHOOSE(Scenario,K32,K33,K34) -> 0.365 | L31: =CHOOSE(Scenario,L32,L33,L34) -> 0.365 | M31: FY2026 36.5%; 1Q FY2027 39.3% helped by one-off US tariff refund (non-recurring). Bear: FY2024-style inventory correction (30.2% then) but milder
A32: Base | H32: 0.37 | I32: 0.365 | J32: 0.365 | K32: 0.365 | L32: 0.365
A33: Bull | H33: 0.375 | I33: 0.375 | J33: 0.38 | K33: 0.38 | L33: 0.38
A34: Bear | H34: 0.355 | I34: 0.34 | J34: 0.35 | K34: 0.35 | L34: 0.35
A35: SG&A, % of revenue (live) | B35: % | H35: =CHOOSE(Scenario,H36,H37,H38) -> 0.233 | I35: =CHOOSE(Scenario,I36,I37,I38) -> 0.23 | J35: =CHOOSE(Scenario,J36,J37,J38) -> 0.228 | K35: =CHOOSE(Scenario,K36,K37,K38) -> 0.226 | L35: =CHOOSE(Scenario,L36,L37,L38) -> 0.225 | M35: FY2026 23.1%, 1Q FY2027 24.5% (sales headcount build under Vision FY2030). Base: modest operating leverage
A36: Base | H36: 0.233 | I36: 0.23 | J36: 0.228 | K36: 0.226 | L36: 0.225
A37: Bull | H37: 0.23 | I37: 0.225 | J37: 0.22 | K37: 0.218 | L37: 0.215
A38: Bear | H38: 0.238 | I38: 0.238 | J38: 0.235 | K38: 0.235 | L38: 0.235
A39: Receivable days (on revenue) (live) | B39: days | H39: =CHOOSE(Scenario,H40,H41,H42) -> 57 | I39: =CHOOSE(Scenario,I40,I41,I42) -> 57 | J39: =CHOOSE(Scenario,J40,J41,J42) -> 57 | K39: =CHOOSE(Scenario,K40,K41,K42) -> 57 | L39: =CHOOSE(Scenario,L40,L41,L42) -> 57 | M39: FY2018-26 range 51-60; FY2026 57
A40: Base | H40: 57 | I40: 57 | J40: 57 | K40: 57 | L40: 57
A41: Bull | H41: 55 | I41: 55 | J41: 55 | K41: 55 | L41: 55
A42: Bear | H42: 60 | I42: 60 | J42: 60 | K42: 60 | L42: 60
...

Sheet Drivers
A1: Drivers: revenue build by customer region
A2: Revenue_t = Revenue_t-1 x (1 + local-currency growth) x (FX_t / FX_t-1)
A4: JPY m, FY ending March | C4: FY2022A | D4: FY2023A | E4: FY2024A | F4: FY2025A | G4: FY2026A | H4: FY2027E | I4: FY2028E | J4: FY2029E | K4: FY2030E | L4: FY2031E | M4: Source / note
A6: FX (fiscal-year average)
A7: USD/JPY | C7: 112.39 | D7: 135.5 | E7: 144.59 | F7: 152.62 | G7: 150.67 | H7: =Assumptions!H23 -> 158.26 | I7: =Assumptions!I23 -> 157.82 | J7: =Assumptions!J23 -> 157.82 | K7: =Assumptions!K23 -> 157.82 | L7: =Assumptions!L23 -> 157.82 | M7: Historical: Makita releases; forecast: Assumptions
A8: EUR/JPY | C8: 130.55 | D8: 140.99 | E8: 156.75 | F8: 163.88 | G8: 174.64 | H8: =Assumptions!H27 -> 178.38 | I8: =Assumptions!I27 -> 176.03 | J8: =Assumptions!J27 -> 176.03 | K8: =Assumptions!K27 -> 176.03 | L8: =Assumptions!L27 -> 176.03
A10: Europe (FX proxy: EUR)
A11: Revenue: Europe | C11: 352470 | D11: 348994 | E11: 356491 | F11: 371798 | G11: 390110 | H11: =G11*(1+Assumptions!H7)*(H8/G8) -> 398464.39 | I11: =H11*(1+Assumptions!I7)*(I8/H8) -> 403045.35 | J11: =I11*(1+Assumptions!J7)*(J8/I8) -> 415136.71 | K11: =J11*(1+Assumptions!K7)*(K8/J8) -> 427590.81 | L11: =K11*(1+Assumptions!L7)*(L8/K8) -> 440418.54 | M11: Makita revenue by customer location
A12: Growth in JPY | C12: ="" | D12: =IFERROR(D11/C11-1,"") -> -0.0098618322 | E12: =IFERROR(E11/D11-1,"") -> 0.021481745 | F12: =IFERROR(F11/E11-1,"") -> 0.04293797 | G12: =IFERROR(G11/F11-1,"") -> 0.049252551 | H12: =H11/G11-1 -> 0.021415483 | I12: =I11/H11-1 -> 0.011496524 | J12: =J11/I11-1 -> 0.03 | K12: =K11/J11-1 -> 0.03 | L12: =L11/K11-1 -> 0.03
A13: Implied local-currency growth | C13: ="" | D13: =(D11/C11)/(D8/C8)-1 -> -0.08317939 | E13: =(E11/D11)/(E8/D8)-1 -> -0.081220343 | F13: =(F11/E11)/(F8/E8)-1 -> -0.0024375955 | G13: =(G11/F11)/(G8/F8)-1 -> -0.01539448 | H13: =Assumptions!H7 -> 0 | I13: =Assumptions!I7 -> 0.025 | J13: =Assumptions!J7 -> 0.03 | K13: =Assumptions!K7 -> 0.03 | L13: =Assumptions!L7 -> 0.03 | M13: Historical: JPY growth stripped of FX; forecast: assumption
A15: Japan (JPY)
A16: Revenue: Japan | C16: 118050 | D16: 122978 | E16: 123222 | F16: 127168 | G16: 132136 | H16: =G16*(1+Assumptions!H11) -> 135439.4 | I16: =H16*(1+Assumptions!I11) -> 138148.19 | J16: =I16*(1+Assumptions!J11) -> 140911.15 | K16: =J16*(1+Assumptions!K11) -> 143729.37 | L16: =K16*(1+Assumptions!L11) -> 145885.32 | M16: Makita revenue by customer location
A17: Growth in JPY | C17: ="" | D17: =IFERROR(D16/C16-1,"") -> 0.041745023 | E17: =IFERROR(E16/D16-1,"") -> 0.0019840947 | F17: =IFERROR(F16/E16-1,"") -> 0.032023502 | G17: =IFERROR(G16/F16-1,"") -> 0.039066432 | H17: =H16/G16-1 -> 0.025 | I17: =I16/H16-1 -> 0.02 | J17: =J16/I16-1 -> 0.02 | K17: =K16/J16-1 -> 0.02 | L17: =L16/K16-1 -> 0.015
A18: Implied local-currency growth | C18: ="" | D18: =D16/C16-1 -> 0.041745023 | E18: =E16/D16-1 -> 0.0019840947 | F18: =F16/E16-1 -> 0.032023502 | G18: =G16/F16-1 -> 0.039066432 | H18: =Assumptions!H11 -> 0.025 | I18: =Assumptions!I11 -> 0.02 | J18: =Assumptions!J11 -> 0.02 | K18: =Assumptions!K11 -> 0.02 | L18: =Assumptions!L11 -> 0.015 | M18: Historical: JPY growth stripped of FX; forecast: assumption
A20: North America (FX proxy: USD)
A21: Revenue: North America | C21: 112248 | D21: 119064 | E21: 93677 | F21: 83919 | G21: 78662 | H21: =G21*(1+Assumptions!H15)*(H7/G7) -> 85103.336 | I21: =H21*(1+Assumptions!I15)*(I7/H7) -> 87412.73 | J21: =I21*(1+Assumptions!J15)*(J7/I7) -> 90035.112 | K21: =J21*(1+Assumptions!K15)*(K7/J7) -> 92736.165 | L21: =K21*(1+Assumptions!L15)*(L7/K7) -> 95518.25 | M21: Makita revenue by customer location
A22: Growth in JPY | C22: ="" | D22: =IFERROR(D21/C21-1,"") -> 0.060722685 | E22: =IFERROR(E21/D21-1,"") -> -0.21322146 | F22: =IFERROR(F21/E21-1,"") -> -0.10416644 | G22: =IFERROR(G21/F21-1,"") -> -0.06264374 | H22: =H21/G21-1 -> 0.081886241 | I22: =I21/H21-1 -> 0.027136358 | J22: =J21/I21-1 -> 0.03 | K22: =K21/J21-1 -> 0.03 | L22: =L21/K21-1 -> 0.03
A23: Implied local-currency growth | C23: ="" | D23: =(D21/C21)/(D7/C7)-1 -> -0.12018729 | E23: =(E21/D21)/(E7/D7)-1 -> -0.2626842 | F23: =(F21/E21)/(F7/E7)-1 -> -0.15130013 | G23: =(G21/F21)/(G7/F7)-1 -> -0.050512296 | H23: =Assumptions!H15 -> 0.03 | I23: =Assumptions!I15 -> 0.03 | J23: =Assumptions!J15 -> 0.03 | K23: =Assumptions!K15 -> 0.03 | L23: =Assumptions!L15 -> 0.03 | M23: Historical: JPY growth stripped of FX; forecast: assumption
A25: Rest of world (FX proxy: USD)
A26: Revenue: Rest of world | C26: 156492 | D26: 173666 | E26: 168001 | F26: 170246 | G26: 176692 | H26: =G26*(1+Assumptions!H19)*(H7/G7) -> 189304.72 | I26: =H26*(1+Assumptions!I19)*(I7/H7) -> 195385.65 | J26: =I26*(1+Assumptions!J19)*(J7/I7) -> 203201.07 | K26: =J26*(1+Assumptions!K19)*(K7/J7) -> 211329.12 | L26: =K26*(1+Assumptions!L19)*(L7/K7) -> 218725.64 | M26: Makita revenue by customer location
A27: Growth in JPY | C27: ="" | D27: =IFERROR(D26/C26-1,"") -> 0.10974363 | E27: =IFERROR(E26/D26-1,"") -> -0.032620087 | F27: =IFERROR(F26/E26-1,"") -> 0.013363016 | G27: =IFERROR(G26/F26-1,"") -> 0.037862857 | H27: =H26/G26-1 -> 0.071382492 | I27: =I26/H26-1 -> 0.032122457 | J27: =J26/I26-1 -> 0.04 | K27: =K26/J26-1 -> 0.04 | L27: =L26/K26-1 -> 0.035
A28: Implied local-currency growth | C28: ="" | D28: =(D26/C26)/(D7/C7)-1 -> -0.079527037 | E28: =(E26/D26)/(E7/D7)-1 -> -0.093436764 | F28: =(F26/E26)/(F7/E7)-1 -> -0.039954407 | G28: =(G26/F26)/(G7/F7)-1 -> 0.051295077 | H28: =Assumptions!H19 -> 0.02 | I28: =Assumptions!I19 -> 0.035 | J28: =Assumptions!J19 -> 0.04 | K28: =Assumptions!K19 -> 0.04 | L28: =Assumptions!L19 -> 0.035 | M28: Historical: JPY growth stripped of FX; forecast: assumption
A30: Total
A31: Total revenue | C31: =C11+C16+C21+C26 -> 739260 | D31: =D11+D16+D21+D26 -> 764702 | E31: =E11+E16+E21+E26 -> 741391 | F31: =F11+F16+F21+F26 -> 753131 | G31: =G11+G16+G21+G26 -> 777600 | H31: =H11+H16+H21+H26 -> 808311.84 | I31: =I11+I16+I21+I26 -> 823991.92 | J31: =J11+J16+J21+J26 -> 849284.05 | ... L31: =L11+L16+L21+L26 -> 900547.74
A32: Growth | C32: ="" | D32: =D31/C31-1 -> 0.034415497 | E32: =E31/D31-1 -> -0.03048377 | F32: =F31/E31-1 -> 0.015835099 | G32: =G31/F31-1 -> 0.0324897 | H32: =H31/G31-1 -> 0.039495685 | I32: =I31/H31-1 -> 0.019398541 | J32: =J31/I31-1 -> 0.030694636 | K32: =K31/J31-1 -> 0.03073344 | L32: =L31/K31-1 -> 0.028744216
A33: of which FX translation (approx.) | H33: =(H31-SUMPRODUCT(G11*(1+Assumptions!H7)+G16*(1+Assumptions!H11)+G21*(1+Assumptions!H15)+G26*(1+Assumptions!H19)))/G31 -> 0.027668139 | I33: =(I31-SUMPRODUCT(H11*(1+Assumptions!I7)+H16*(1+Assumptions!I11)+H21*(1+Assumptions!I15)+H26*(1+Assumptions!I19)))/H31 -> -0.0076320696 | J33: =(J31-SUMPRODUCT(I11*(1+Assumptions!J7)+I16*(1+Assumptions!J11)+I21*(1+Assumptions!J15)+I26*(1+Assumptions!J19)))/I31 -> 0 | K33: =(K31-SUMPRODUCT(J11*(1+Assumptions!K7)+J16*(1+Assumptions!K11)+J21*(1+Assumptions!K15)+J26*(1+Assumptions!K19)))/J31 -> 0 | L33: =(L31-SUMPRODUCT(K11*(1+Assumptions!L7)+K16*(1+Assumptions!L11)+K21*(1+Assumptions!L15)+K26*(1+Assumptions!L19)))/K31 -> 0 | M33: Revenue growth from FX alone, holding local-currency volumes

Sheet IS
A1: Income statement
A2: IFRS. Historical from Makita earnings releases (data/clean/makita_is.csv)
A4: JPY m, FY ending March | C4: FY2022A | D4: FY2023A | E4: FY2024A | F4: FY2025A | G4: FY2026A | H4: FY2027E | I4: FY2028E | J4: FY2029E | K4: FY2030E | L4: FY2031E | M4: Source / note
A5: Revenue | C5: 739260 | D5: 764702 | E5: 741391 | F5: 753130 | G5: 777600 | H5: =Drivers!H31 -> 808311.84 | I5: =Drivers!I31 -> 823991.92 | J5: =Drivers!J31 -> 849284.05 | K5: =Drivers!K31 -> 875385.47 | L5: =Drivers!L31 -> 900547.74 | M5: Forecast: Drivers sheet regional build
A6: Growth | C6: ="" | D6: =IFERROR(D5/C5-1,"") -> 0.034415497 | E6: =IFERROR(E5/D5-1,"") -> -0.03048377 | F6: =IFERROR(F5/E5-1,"") -> 0.01583375 | G6: =IFERROR(G5/F5-1,"") -> 0.032491071 | H6: =H5/G5-1 -> 0.039495685 | I6: =I5/H5-1 -> 0.019398541 | J6: =J5/I5-1 -> 0.030694636 | K6: =K5/J5-1 -> 0.03073344 | L6: =L5/K5-1 -> 0.028744216
A7: Cost of sales | C7: -510942 | D7: -575954 | E7: -517446 | F7: -481704 | G7: -493630 | H7: =-H5*(1-Assumptions!H31) -> -509236.46 | I7: =-I5*(1-Assumptions!I31) -> -523234.87 | J7: =-J5*(1-Assumptions!J31) -> -539295.37 | K7: =-K5*(1-Assumptions!K31) -> -555869.77 | L7: =-L5*(1-Assumptions!L31) -> -571847.81
A8: Gross profit | C8: =C5+C7 -> 228318 | D8: =D5+D7 -> 188748 | E8: =E5+E7 -> 223945 | F8: =F5+F7 -> 271426 | G8: =G5+G7 -> 283970 | H8: =H5+H7 -> 299075.38 | I8: =I5+I7 -> 300757.05 | J8: =J5+J7 -> 309988.68 | ... L8: =L5+L7 -> 328699.92
A9: Gross margin | C9: =C8/C5 -> 0.30884668 | D9: =D8/D5 -> 0.24682556 | E9: =E8/E5 -> 0.30206059 | F9: =F8/F5 -> 0.36039728 | G9: =G8/G5 -> 0.36518776 | H9: =H8/H5 -> 0.37 | I9: =I8/I5 -> 0.365 | J9: =J8/J5 -> 0.365 | ... L9: =L8/L5 -> 0.365
A10: SG&A and other, net | C10: -136590 | D10: -160502 | E10: -157776 | F10: -164388 | G10: -179266 | H10: =-H5*Assumptions!H35 -> -188336.66 | I10: =-I5*Assumptions!I35 -> -189518.14 | J10: =-J5*Assumptions!J35 -> -193636.76 | K10: =-K5*Assumptions!K35 -> -197837.12 | L10: =-L5*Assumptions!L35 -> -202623.24
A11: Operating profit | C11: =C8+C10 -> 91728 | D11: =D8+D10 -> 28246 | E11: =E8+E10 -> 66169 | F11: =F8+F10 -> 107038 | G11: =G8+G10 -> 104704 | H11: =H8+H10 -> 110738.72 | I11: =I8+I10 -> 111238.91 | J11: =J8+J10 -> 116351.91 | ... L11: =L8+L10 -> 126076.68
A12: Operating margin | C12: =C11/C5 -> 0.12408084 | D12: =D11/D5 -> 0.036937264 | E12: =E11/E5 -> 0.089249802 | F12: =F11/F5 -> 0.1421242 | G12: =G11/G5 -> 0.13465021 | H12: =H11/H5 -> 0.137 | I12: =I11/I5 -> 0.135 | J12: =J11/J5 -> 0.137 | ... L12: =L11/L5 -> 0.14
A13: Financial income | C13: 1937 | D13: 3316 | E13: 4643 | F13: 7450 | G13: 6896 | H13: =Assumptions!$G$73*(BS!G7+BS!G8) -> 5239.278 | I13: =Assumptions!$G$73*(BS!H7+BS!H8) -> 5786.3648 | J13: =Assumptions!$G$73*(BS!I7+BS!I8) -> 6510.3343 | K13: =Assumptions!$G$73*(BS!J7+BS!J8) -> 7237.1987 | L13: =Assumptions!$G$73*(BS!K7+BS!K8) -> 7938.2702 | M13: Forecast: yield x opening cash and deposits (no circularity)
A14: Financial expenses | C14: -1182 | D14: -7675 | E14: -6795 | F14: -6011 | G14: -3584 | H14: =Assumptions!$G$74 -> -1200 | I14: =Assumptions!$G$74 -> -1200 | J14: =Assumptions!$G$74 -> -1200 | K14: =Assumptions!$G$74 -> -1200 | L14: =Assumptions!$G$74 -> -1200
A15: Profit before tax | C15: =C11+C13+C14 -> 92483 | D15: =D11+D13+D14 -> 23887 | E15: =E11+E13+E14 -> 64017 | F15: =F11+F13+F14 -> 108477 | G15: =G11+G13+G14 -> 108016 | H15: =H11+H13+H14 -> 114778 | I15: =I11+I13+I14 -> 115825.27 | J15: =J11+J13+J14 -> 121662.25 | ... L15: =L11+L13+L14 -> 132814.95
A16: Income tax | C16: -27146 | D16: -12316 | E16: -20402 | F16: -29274 | G16: -28579 | H16: =-H15*Assumptions!$G$70 -> -30990.06 | I16: =-I15*Assumptions!$G$70 -> -31272.824 | J16: =-J15*Assumptions!$G$70 -> -32848.807 | K16: =-K15*Assumptions!$G$70 -> -34483.26 | L16: =-L15*Assumptions!$G$70 -> -35860.037
A17: Effective tax rate | C17: =-C16/C15 -> 0.29352422 | D17: =-D16/D15 -> 0.51559426 | E17: =-E16/E15 -> 0.3186966 | F17: =-F16/F15 -> 0.26986366 | G17: =-G16/G15 -> 0.26458117 | H17: =-H16/H15 -> 0.27 | I17: =-I16/I15 -> 0.27 | J17: =-J16/J15 -> 0.27 | ... L17: =-L16/L15 -> 0.27
A18: Profit | C18: =C15+C16 -> 65337 | D18: =D15+D16 -> 11571 | E18: =E15+E16 -> 43615 | F18: =F15+F16 -> 79203 | G18: =G15+G16 -> 79437 | H18: =H15+H16 -> 83787.941 | I18: =I15+I16 -> 84552.45 | J18: =J15+J16 -> 88813.442 | ... L18: =L15+L16 -> 96954.916
A19: attributable to non-controlling interests | C19: 567 | D19: -134 | E19: -76 | F19: -135 | G19: 24 | H19: =H18*Assumptions!$G$75 -> 83.787941 | I19: =I18*Assumptions!$G$75 -> 84.55245 | J19: =J18*Assumptions!$G$75 -> 88.813442 | K19: =K18*Assumptions!$G$75 -> 93.232519 | L19: =L18*Assumptions!$G$75 -> 96.954916
A20: attributable to owners of the parent | C20: =C18-C19 -> 64770 | D20: =D18-D19 -> 11705 | E20: =E18-E19 -> 43691 | F20: =F18-F19 -> 79338 | G20: =G18-G19 -> 79413 | H20: =H18-H19 -> 83704.153 | I20: =I18-I19 -> 84467.897 | J20: =J18-J19 -> 88724.628 | ... L20: =L18-L19 -> 96857.961
A22: Per share
A23: Average shares (m) | C23: 271.53097 | D23: 271.5391 | E23: 269.48491 | F23: 269.03133 | G23: 264.75426 | H23: =Assumptions!$D$86-Assumptions!H63/Assumptions!$D$85/2 -> 257.65551 | I23: =H23-(Assumptions!H63+Assumptions!I63)/Assumptions!$D$85/2 -> 257.65551 | J23: =I23-(Assumptions!I63+Assumptions!J63)/Assumptions!$D$85/2 -> 257.65551 | K23: =J23-(Assumptions!J63+Assumptions!K63)/Assumptions!$D$85/2 -> 257.65551 | L23: =K23-(Assumptions!K63+Assumptions!L63)/Assumptions!$D$85/2 -> 257.65551 | M23: Forecast: 30 Jun 2026 count less buybacks at today's price (mid-year)
A24: EPS (JPY) | C24: =C20/C23 -> 238.53633 | D24: =D20/D23 -> 43.10613 | E24: =E20/E23 -> 162.12782 | F24: =F20/F23 -> 294.90246 | G24: =G20/G23 -> 299.94984 | H24: =H20/H23 -> 324.86847 | I24: =I20/I23 -> 327.83268 | J24: =J20/J23 -> 344.3537 | ... L24: =L20/L23 -> 375.92039
A25: DPS (JPY) | C25: 72 | D25: 21 | E25: 57 | F25: 110 | G25: 150 | H25: =H24*Assumptions!$G$76 -> 162.43424 | I25: =I24*Assumptions!$G$76 -> 163.91634 | J25: =J24*Assumptions!$G$76 -> 172.17685 | K25: =K24*Assumptions!$G$76 -> 180.74383 | L25: =L24*Assumptions!$G$76 -> 187.9602
A27: Memo
A28: D&A total (incl. right-of-use) | C28: 21002 | D28: 25889 | E28: 28925 | F28: 29757 | G28: 30465 | H28: =CF!H10 -> 31356.752 | I28: =CF!I10 -> 31764.603 | J28: =CF!J10 -> 32109.036 | K28: =CF!K10 -> 32364.942 | L28: =CF!L10 -> 32684.847
A29: EBITDA (IFRS 16) | C29: =C11+C28 -> 112730 | D29: =D11+D28 -> 54135 | E29: =E11+E28 -> 95094 | F29: =F11+F28 -> 136795 | G29: =G11+G28 -> 135169 | H29: =H11+H28 -> 142095.47 | I29: =I11+I28 -> 143003.51 | J29: =J11+J28 -> 148460.95 | ... L29: =L11+L28 -> 158761.53
A30: EBITDA margin | C30: =C29/C5 -> 0.15249033 | D30: =D29/D5 -> 0.070792282 | E30: =E29/E5 -> 0.1282643 | F30: =F29/F5 -> 0.18163531 | G30: =G29/G5 -> 0.17382845 | H30: =H29/H5 -> 0.17579289 | I30: =I29/I5 -> 0.17354965 | J30: =J29/J5 -> 0.17480718 | ... L30: =L29/L5 -> 0.17629441

Sheet BS
A1: Balance sheet
A2: Condensed from the IFRS statement of financial position (data/clean/makita_bs.csv)
A4: JPY m, FY ending March | C4: FY2022A | D4: FY2023A | E4: FY2024A | F4: FY2025A | G4: FY2026A | H4: FY2027E | I4: FY2028E | J4: FY2029E | K4: FY2030E | L4: FY2031E | M4: Source / note
A6: Assets
A7: Cash and cash equivalents | C7: 71057 | D7: 162720 | E7: 196645 | F7: 253279 | G7: 257385 | H7: =CF!H35 -> 287778.71 | I7: =CF!I35 -> 327999.24 | J7: =CF!J35 -> 368380.6 | K7: =CF!K35 -> 407329.01 | L7: =CF!L35 -> 446706.78 | M7: Forecast: from cash-flow statement
A8: Other current financial assets (mainly time deposits) | C8: 5281 | D8: 6970 | E8: 18561 | F8: 39660 | G8: 33686 | H8: =G8 -> 33686 | I8: =H8 -> 33686 | J8: =I8 -> 33686 | K8: =J8 -> 33686 | L8: =K8 -> 33686 | M8: Held flat
A9: Trade and other receivables | C9: 117541 | D9: 110884 | E9: 116267 | F9: 105831 | G9: 122018 | H9: =IS!H5*Assumptions!H39/365 -> 126229.52 | I9: =IS!I5*Assumptions!I39/365 -> 128678.19 | J9: =IS!J5*Assumptions!J39/365 -> 132627.92 | K9: =IS!K5*Assumptions!K39/365 -> 136704.03 | L9: =IS!L5*Assumptions!L39/365 -> 140633.48
A10: Inventories | C10: 475128 | D10: 453752 | E10: 345491 | F10: 338116 | G10: 375829 | H10: =-IS!H7*Assumptions!H43/365 -> 383671.31 | I10: =-IS!I7*Assumptions!I43/365 -> 384183.41 | J10: =-IS!J7*Assumptions!J43/365 -> 387110.65 | K10: =-IS!K7*Assumptions!K43/365 -> 392916.17 | L10: =-IS!L7*Assumptions!L43/365 -> 399510.12
A11: Other current assets | C11: 15952 | D11: 19113 | E11: 16671 | F11: 19552 | G11: 19273 | H11: =IS!H5*Assumptions!H51 -> 20207.796 | I11: =IS!I5*Assumptions!I51 -> 20599.798 | J11: =IS!J5*Assumptions!J51 -> 21232.101 | K11: =IS!K5*Assumptions!K51 -> 21884.637 | L11: =IS!L5*Assumptions!L51 -> 22513.693
A12: Total current assets | C12: =SUM(C7:C11) -> 684959 | D12: =SUM(D7:D11) -> 753439 | E12: =SUM(E7:E11) -> 693635 | F12: =SUM(F7:F11) -> 756438 | G12: =SUM(G7:G11) -> 808191 | H12: =SUM(H7:H11) -> 851573.33 | I12: =SUM(I7:I11) -> 895146.64 | J12: =SUM(J7:J11) -> 943037.27 | ... L12: =SUM(L7:L11) -> 1043050.1
A13: Property, plant and equipment (incl. right-of-use) | C13: 243636 | D13: 265638 | E13: 277248 | F13: 266609 | G13: 278067 | H13: =G13+CF!H38-CF!H8 -> 281306 | I13: =H13+CF!I38-CF!I8 -> 283160.26 | J13: =I13+CF!J38-CF!J8 -> 284003.45 | K13: =J13+CF!K38-CF!K8 -> 285603.46 | L13: =K13+CF!L38-CF!L8 -> 287859.87 | M13: Opening + capex - depreciation ex-ROU (ROU asset held flat: new leases = ROU depreciation)
A14: Goodwill and intangible assets | C14: 10085 | D14: 10427 | E14: 10206 | F14: 9574 | G14: 9619 | H14: =G14 -> 9619 | I14: =H14 -> 9619 | J14: =I14 -> 9619 | K14: =J14 -> 9619 | L14: =K14 -> 9619 | M14: Held flat
A15: Other non-current assets (investments, pension, deferred tax) | C15: 68817 | D15: 69847 | E15: 74719 | F15: 73905 | G15: 85308 | H15: =G15 -> 85308 | I15: =H15 -> 85308 | J15: =I15 -> 85308 | K15: =J15 -> 85308 | L15: =K15 -> 85308 | M15: Held flat
A16: Total non-current assets | C16: =SUM(C13:C15) -> 322538 | D16: =SUM(D13:D15) -> 345912 | E16: =SUM(E13:E15) -> 362173 | F16: =SUM(F13:F15) -> 350088 | G16: =SUM(G13:G15) -> 372994 | H16: =SUM(H13:H15) -> 376233 | I16: =SUM(I13:I15) -> 378087.26 | J16: =SUM(J13:J15) -> 378930.45 | ... L16: =SUM(L13:L15) -> 382786.87
A17: Total assets | C17: =C12+C16 -> 1007497 | D17: =D12+D16 -> 1099351 | E17: =E12+E16 -> 1055808 | F17: =F12+F16 -> 1106526 | G17: =G12+G16 -> 1181185 | H17: =H12+H16 -> 1227806.3 | I17: =I12+I16 -> 1273233.9 | J17: =J12+J16 -> 1321967.7 | ... L17: =L12+L16 -> 1425836.9
A19: Liabilities
A20: Trade and other payables | C20: 67274 | D20: 41767 | E20: 49987 | F20: 54628 | G20: 55358 | H20: =-IS!H7*Assumptions!H47/365 -> 57201.904 | I20: =-IS!I7*Assumptions!I47/365 -> 58774.327 | J20: =-IS!J7*Assumptions!J47/365 -> 60578.384 | K20: =-IS!K7*Assumptions!K47/365 -> 62440.166 | L20: =-IS!L7*Assumptions!L47/365 -> 64234.96
A21: Borrowings | C21: 79674 | D21: 186390 | E21: 19891 | F21: 10152 | G21: 2384 | H21: =G21+CF!H27 -> 2384 | I21: =H21+CF!I27 -> 2384 | J21: =I21+CF!J27 -> 2384 | K21: =J21+CF!K27 -> 2384 | L21: =K21+CF!L27 -> 2384 | M21: Base borrowings flat + revolver (CF)
A22: Other financial liabilities (mainly leases) | C22: 23842 | D22: 22339 | E22: 23217 | F22: 22323 | G22: 20030 | H22: =G22 -> 20030 | I22: =H22 -> 20030 | J22: =I22 -> 20030 | K22: =J22 -> 20030 | L22: =K22 -> 20030 | M22: Held flat
A23: Other operating liabilities (tax payable, provisions, other) | C23: 67329 | D23: 55932 | E23: 69530 | F23: 67478 | G23: 76373 | H23: =IS!H5*Assumptions!H55 -> 79214.561 | I23: =IS!I5*Assumptions!I55 -> 80751.208 | J23: =IS!J5*Assumptions!J55 -> 83229.837 | K23: =IS!K5*Assumptions!K55 -> 85787.776 | L23: =IS!L5*Assumptions!L55 -> 88253.678
A24: Other non-current liabilities (pension, provisions, deferred tax) | C24: 16848 | D24: 17224 | E24: 17977 | F24: 19448 | G24: 22498 | H24: =G24 -> 22498 | I24: =H24 -> 22498 | J24: =I24 -> 22498 | K24: =J24 -> 22498 | L24: =K24 -> 22498 | M24: Held flat
A25: Total liabilities | C25: =SUM(C20:C24) -> 254967 | D25: =SUM(D20:D24) -> 323652 | E25: =SUM(E20:E24) -> 180602 | F25: =SUM(F20:F24) -> 174029 | G25: =SUM(G20:G24) -> 176643 | H25: =SUM(H20:H24) -> 181328.46 | I25: =SUM(I20:I24) -> 184437.54 | J25: =SUM(J20:J24) -> 188720.22 | ... L25: =SUM(L20:L24) -> 197400.64
A27: Equity
A28: Share capital and capital surplus | C28: 69390 | D28: 69411 | E28: 69412 | F28: 69819 | G28: 69237 | H28: =G28 -> 69237 | I28: =H28 -> 69237 | J28: =I28 -> 69237 | K28: =J28 -> 69237 | L28: =K28 -> 69237
A29: Retained earnings | C29: 640577 | D29: 629314 | E29: 669359 | F29: 732556 | G29: 779488 | H29: =G29+IS!H20+CF!H24 -> 821340.08 | I29: =H29+IS!I20+CF!I24 -> 863574.02 | J29: =I29+IS!J20+CF!J24 -> 907936.34 | K29: =J29+IS!K20+CF!K24 -> 954505.98 | L29: =K29+IS!L20+CF!L24 -> 1002935
A30: Treasury shares | C30: -11540 | D30: -11528 | E30: -21501 | F30: -21470 | G30: -76727 | H30: =G30+CF!H25 -> -76727 | I30: =H30+CF!I25 -> -76727 | J30: =I30+CF!J25 -> -76727 | K30: =J30+CF!K25 -> -76727 | L30: =K30+CF!L25 -> -76727
A31: Other components of equity | C31: 47917 | D31: 82050 | E31: 150886 | F31: 145101 | G31: 225342 | H31: =G31 -> 225342 | I31: =H31 -> 225342 | J31: =I31 -> 225342 | K31: =J31 -> 225342 | L31: =K31 -> 225342 | M31: Held flat: no forecast of FX translation reserve
A32: Equity attributable to owners of the parent | C32: =SUM(C28:C31) -> 746344 | D32: =SUM(D28:D31) -> 769247 | E32: =SUM(E28:E31) -> 868156 | F32: =SUM(F28:F31) -> 926006 | G32: =SUM(G28:G31) -> 997340 | H32: =SUM(H28:H31) -> 1039192.1 | I32: =SUM(I28:I31) -> 1081426 | J32: =SUM(J28:J31) -> 1125788.3 | ... L32: =SUM(L28:L31) -> 1220787
A33: Non-controlling interests | C33: 6186 | D33: 6452 | E33: 7050 | F33: 6490 | G33: 7201 | H33: =G33+IS!H19 -> 7284.7879 | I33: =H33+IS!I19 -> 7369.3404 | J33: =I33+IS!J19 -> 7458.1538 | K33: =J33+IS!K19 -> 7551.3864 | L33: =K33+IS!L19 -> 7648.3413
A34: Total equity | C34: =C32+C33 -> 752530 | D34: =D32+D33 -> 775699 | E34: =E32+E33 -> 875206 | F34: =F32+F33 -> 932496 | G34: =G32+G33 -> 1004541 | H34: =H32+H33 -> 1046476.9 | I34: =I32+I33 -> 1088795.4 | J34: =J32+J33 -> 1133246.5 | ... L34: =L32+L33 -> 1228435.3
A35: Total liabilities and equity | C35: =C25+C34 -> 1007497 | D35: =D25+D34 -> 1099351 | E35: =E25+E34 -> 1055808 | F35: =F25+F34 -> 1106525 | G35: =G25+G34 -> 1181184 | H35: =H25+H34 -> 1227805.3 | I35: =I25+I34 -> 1273232.9 | J35: =J25+J34 -> 1321966.7 | ... L35: =L25+L34 -> 1425835.9
A36: Check: assets - liabilities - equity | C36: =ROUND(C17-C35,3) -> 0 | D36: =ROUND(D17-D35,3) -> 0 | E36: =ROUND(E17-E35,3) -> 0 | F36: =ROUND(F17-F35,3) -> 1 | G36: =ROUND(G17-G35,3) -> 1 | H36: =ROUND(H17-H35,3) -> 1 | I36: =ROUND(I17-I35,3) -> 1 | J36: =ROUND(J17-J35,3) -> 1 | ... L36: =ROUND(L17-L35,3) -> 1 | M36: Must be zero
A38: Memo
A39: Operating net working capital | C39: =C9+C10+C11-C20-C23 -> 474018 | D39: =D9+D10+D11-D20-D23 -> 486050 | E39: =E9+E10+E11-E20-E23 -> 358912 | F39: =F9+F10+F11-F20-F23 -> 341393 | G39: =G9+G10+G11-G20-G23 -> 385389 | H39: =H9+H10+H11-H20-H23 -> 393692.16 | I39: =I9+I10+I11-I20-I23 -> 393935.86 | J39: =J9+J10+J11-J20-J23 -> 397162.45 | ... L39: =L9+L10+L11-L20-L23 -> 410168.65
A40: Net cash (cash + deposits - borrowings - leases) | C40: =C7+C8-C21-C22 -> -27178 | D40: =D7+D8-D21-D22 -> -39039 | E40: =E7+E8-E21-E22 -> 172098 | F40: =F7+F8-F21-F22 -> 260464 | G40: =G7+G8-G21-G22 -> 268657 | H40: =H7+H8-H21-H22 -> 299050.71 | I40: =I7+I8-I21-I22 -> 339271.24 | J40: =J7+J8-J21-J22 -> 379652.6 | ... L40: =L7+L8-L21-L22 -> 457978.78
A41: ROE (on average parent equity) | C41: ="" | D41: =IS!D20/AVERAGE(D32,C32) -> 0.01544612 | E41: =IS!E20/AVERAGE(E32,D32) -> 0.053366215 | F41: =IS!F20/AVERAGE(F32,E32) -> 0.088440174 | G41: =IS!G20/AVERAGE(G32,F32) -> 0.082577966 | H41: =IS!H20/AVERAGE(H32,G32) -> 0.082202636 | I41: =IS!I20/AVERAGE(I32,H32) -> 0.079663469 | J41: =IS!J20/AVERAGE(J32,I32) -> 0.080395117 | K41: =IS!K20/AVERAGE(K32,J32) -> 0.08105601 | L41: =IS!L20/AVERAGE(L32,K32) -> 0.080946172

Sheet CF
A1: Cash-flow statement
A2: Indirect method. Historical condensed from data/clean/makita_cf.csv
A4: JPY m, FY ending March | C4: FY2022A | D4: FY2023A | E4: FY2024A | F4: FY2025A | G4: FY2026A | H4: FY2027E | I4: FY2028E | J4: FY2029E | K4: FY2030E | L4: FY2031E | M4: Source / note
A6: Operating
A7: Profit | C7: 65337 | D7: 11571 | E7: 43615 | F7: 79203 | G7: 79438 | H7: =IS!H18 -> 83787.941 | I7: =IS!I18 -> 84552.45 | J7: =IS!J18 -> 88813.442 | K7: =IS!K18 -> 93232.519 | L7: =IS!L18 -> 96954.916
A8: Depreciation ex right-of-use | H8: =Assumptions!$G$71*BS!G13 -> 25860.231 | I8: =Assumptions!$G$71*BS!H13 -> 26161.458 | J8: =Assumptions!$G$71*BS!I13 -> 26333.904 | K8: =Assumptions!$G$71*BS!J13 -> 26412.321 | L8: =Assumptions!$G$71*BS!K13 -> 26561.122 | M8: Opening PP&E x rate
A9: Right-of-use depreciation | H9: =IS!H5*Assumptions!$G$72 -> 5496.5205 | I9: =IS!I5*Assumptions!$G$72 -> 5603.145 | J9: =IS!J5*Assumptions!$G$72 -> 5775.1315 | K9: =IS!K5*Assumptions!$G$72 -> 5952.6212 | L9: =IS!L5*Assumptions!$G$72 -> 6123.7246
A10: D&A total | C10: 21002 | D10: 25889 | E10: 28925 | F10: 29757 | G10: 30465 | H10: =H8+H9 -> 31356.752 | I10: =I8+I9 -> 31764.603 | J10: =J8+J9 -> 32109.036 | K10: =K8+K9 -> 32364.942 | L10: =L8+L9 -> 32684.847
A11: (Increase) / decrease in receivables | C11: -14153 | D11: 12488 | E11: 4940 | F11: 8792 | G11: -5563 | H11: =BS!G9-BS!H9 -> -4211.521 | I11: =BS!H9-BS!I9 -> -2448.6686 | J11: =BS!I9-BS!J9 -> -3949.7302 | K11: =BS!J9-BS!K9 -> -4076.1123 | L11: =BS!K9-BS!L9 -> -3929.4502
A12: (Increase) / decrease in inventories | C12: -175557 | D12: 48571 | E12: 151378 | F12: 4112 | G12: -2695 | H12: =BS!G10-BS!H10 -> -7842.3072 | I12: =BS!H10-BS!I10 -> -512.10154 | J12: =BS!I10-BS!J10 -> -2927.2406 | K12: =BS!J10-BS!K10 -> -5805.5185 | L12: =BS!K10-BS!L10 -> -6593.9482
A13: Increase / (decrease) in payables | C13: 1295 | D13: -27155 | E13: 4661 | F13: 6124 | G13: -4350 | H13: =BS!H20-BS!G20 -> 1843.904 | I13: =BS!I20-BS!H20 -> 1572.4235 | J13: =BS!J20-BS!I20 -> 1804.0566 | K13: =BS!K20-BS!J20 -> 1861.7822 | L13: =BS!L20-BS!K20 -> 1794.7936
A14: Other working capital | H14: =(BS!G11-BS!H11)+(BS!H23-BS!G23) -> 1906.7647 | I14: =(BS!H11-BS!I11)+(BS!I23-BS!H23) -> 1144.6452 | J14: =(BS!I11-BS!J11)+(BS!J23-BS!I23) -> 1846.3256 | K14: =(BS!J11-BS!K11)+(BS!K23-BS!J23) -> 1905.4037 | L14: =(BS!K11-BS!L11)+(BS!L23-BS!K23) -> 1836.8456
A15: Other operating items (historical: tax, interest, other) | C15: =C16-SUM(C7:C14) -> -1584 | D15: =D16-SUM(D7:D14) -> -26934 | E15: =E16-SUM(E7:E14) -> 3567 | F15: =F16-SUM(F7:F14) -> 1886 | G15: =G16-SUM(G7:G14) -> 5041 | M15: Historical plug to reported CFO; forecast: cash taxes = tax expense
A16: Cash flow from operations | C16: -103660 | D16: 44430 | E16: 237086 | F16: 129874 | G16: 102336 | H16: =SUM(H7:H14)-H8-H9 -> 106841.53 | I16: =SUM(I7:I14)-I8-I9 -> 116073.35 | J16: =SUM(J7:J14)-J8-J9 -> 117695.89 | K16: =SUM(K7:K14)-K8-K9 -> 119483.02 | L16: =SUM(L7:L14)-L8-L9 -> 122748 | M16: Forecast sums profit, D&A total and working capital (dep/ROU rows are components of D&A total)
A18: Investing
A19: Capex (purchase of non-current assets) | C19: -59937 | D19: -39088 | E19: -17851 | F19: -17594 | G19: -21532 | H19: =-H38 -> -29099.226 | I19: =-I38 -> -28015.725 | J19: =-J38 -> -27177.09 | K19: =-K38 -> -28012.335 | L19: =-L38 -> -28817.528
A20: Other investing (time deposits, investments) | C20: =C21-C19 -> 32046 | D20: =D21-D19 -> 1408 | E20: =E21-E19 -> -7768 | F20: =F21-F19 -> -20278 | G20: =G21-G19 -> 3898 | H20: =0 -> 0 | I20: =0 -> 0 | J20: =0 -> 0 | K20: =0 -> 0 | L20: =0 -> 0 | M20: Historical plug; forecast deposits held flat
A21: Cash flow from investing | C21: -27891 | D21: -37680 | E21: -25619 | F21: -37872 | G21: -17634 | H21: =H19+H20 -> -29099.226 | I21: =I19+I20 -> -28015.725 | J21: =J19+J20 -> -27177.09 | K21: =K19+K20 -> -28012.335 | L21: =L19+L20 -> -28817.528
A23: Financing
A24: Dividends paid | C24: -18736 | D24: -19550 | E24: -5677 | F24: -18025 | G24: -29504 | H24: =-IS!H20*Assumptions!$G$76 -> -41852.076 | I24: =-IS!I20*Assumptions!$G$76 -> -42233.949 | J24: =-IS!J20*Assumptions!$G$76 -> -44362.314 | K24: =-IS!K20*Assumptions!$G$76 -> -46569.643 | L24: =-IS!L20*Assumptions!$G$76 -> -48428.981 | M24: Forecast: payout x current-year profit (timing simplification)
A25: Share buybacks | C25: -7 | D25: -1 | E25: -10002 | F25: -3 | G25: -55928 | H25: =-Assumptions!H63 -> 0 | I25: =-Assumptions!I63 -> 0 | J25: =-Assumptions!J63 -> 0 | K25: =-Assumptions!K63 -> 0 | L25: =-Assumptions!L63 -> 0
A26: Repayment of lease liabilities | C26: -3611 | D26: -4376 | E26: -4228 | F26: -5623 | G26: -5151 | H26: =-H9 -> -5496.5205 | I26: =-I9 -> -5603.145 | J26: =-J9 -> -5775.1315 | K26: =-K9 -> -5952.6212 | L26: =-L9 -> -6123.7246
A27: Change in borrowings (revolver) | C27: 75169 | D27: 104874 | E27: -171379 | F27: -9718 | G27: -8586 | H27: =MAX(0,Assumptions!$G$77-(H34+H16+H21+H24+H25+H26-(BS!G21-BS!G21)))-(BS!G21-BS!G21) -> 0 | I27: =MAX(0,Assumptions!$G$77-(I34+I16+I21+I24+I25+I26-(BS!H21-BS!G21)))-(BS!H21-BS!G21) -> 0 | J27: =MAX(0,Assumptions!$G$77-(J34+J16+J21+J24+J25+J26-(BS!I21-BS!G21)))-(BS!I21-BS!G21) -> 0 | K27: =MAX(0,Assumptions!$G$77-(K34+K16+K21+K24+K25+K26-(BS!J21-BS!G21)))-(BS!J21-BS!G21) -> 0 | L27: =MAX(0,Assumptions!$G$77-(L34+L16+L21+L24+L25+L26-(BS!K21-BS!G21)))-(BS!K21-BS!G21) -> 0 | M27: Draws if pre-financing cash < minimum; repays prior draws first
A28: Other financing | C28: =C29-SUM(C24:C27) -> -189 | D28: =D29-SUM(D24:D27) -> 23 | E28: =E29-SUM(E24:E27) -> 9 | F28: =F29-SUM(F24:F27) -> -176 | G28: =G29-SUM(G24:G27) -> 2 | H28: =0 -> 0 | I28: =0 -> 0 | J28: =0 -> 0 | K28: =0 -> 0 | L28: =0 -> 0
A29: Cash flow from financing | C29: 52626 | D29: 80970 | E29: -191277 | F29: -33545 | G29: -99167 | H29: =SUM(H24:H28) -> -47348.597 | I29: =SUM(I24:I28) -> -47837.094 | J29: =SUM(J24:J28) -> -50137.446 | K29: =SUM(K24:K28) -> -52522.264 | L29: =SUM(L24:L28) -> -54552.705
A31: Cash
A32: FX effect on cash | C32: 1342 | D32: 3943 | E32: 13735 | F32: -1824 | G32: 18572 | H32: =0 -> 0 | I32: =0 -> 0 | J32: =0 -> 0 | K32: =0 -> 0 | L32: =0 -> 0 | M32: Not forecast
A33: Net change in cash | C33: =C16+C21+C29+C32 -> -77583 | D33: =D16+D21+D29+D32 -> 91663 | E33: =E16+E21+E29+E32 -> 33925 | F33: =F16+F21+F29+F32 -> 56633 | G33: =G16+G21+G29+G32 -> 4107 | H33: =H16+H21+H29+H32 -> 30393.709 | I33: =I16+I21+I29+I32 -> 40220.532 | J33: =J16+J21+J29+J32 -> 40381.354 | ... L33: =L16+L21+L29+L32 -> 39377.771
A34: Cash at beginning of year | C34: 148640 | D34: 71057 | E34: 162720 | F34: 196645 | G34: 253279 | H34: =BS!G7 -> 257385 | I34: =BS!H7 -> 287778.71 | J34: =BS!I7 -> 327999.24 | K34: =BS!J7 -> 368380.6 | L34: =BS!K7 -> 407329.01
A35: Cash at end of year | C35: =C34+C33 -> 71057 | D35: =D34+D33 -> 162720 | E35: =E34+E33 -> 196645 | F35: =F34+F33 -> 253278 | G35: =G34+G33 -> 257386 | H35: =H34+H33 -> 287778.71 | I35: =I34+I33 -> 327999.24 | J35: =J34+J33 -> 368380.6 | ... L35: =L34+L33 -> 446706.78
A37: Memo
A38: Capex (positive) | C38: =-C19 -> 59937 | D38: =-D19 -> 39088 | E38: =-E19 -> 17851 | F38: =-F19 -> 17594 | G38: =-G19 -> 21532 | H38: =IS!H5*Assumptions!H59 -> 29099.226 | I38: =IS!I5*Assumptions!I59 -> 28015.725 | J38: =IS!J5*Assumptions!J59 -> 27177.09 | K38: =IS!K5*Assumptions!K59 -> 28012.335 | L38: =IS!L5*Assumptions!L59 -> 28817.528
A39: Free cash flow (CFO + capex + lease repayments) | C39: =C16+C19+C26 -> -167208 | D39: =D16+D19+D26 -> 966 | E39: =E16+E19+E26 -> 215007 | F39: =F16+F19+F26 -> 106657 | G39: =G16+G19+G26 -> 75653 | H39: =H16+H19+H26 -> 72245.786 | I39: =I16+I19+I26 -> 82454.481 | J39: =J16+J19+J26 -> 84743.668 | ... L39: =L16+L19+L26 -> 87806.751

Sheet DCF
A1: DCF: unlevered free cash flow
A2: Cash flows from 1 Jul 2026 (after the 30 Jun 2026 balance sheet), mid-period discounting to the valuation date
A4: JPY m, FY ending March | C4: FY2022A | D4: FY2023A | E4: FY2024A | F4: FY2025A | G4: FY2026A | H4: FY2027E | I4: FY2028E | J4: FY2029E | K4: FY2030E | L4: FY2031E | M4: Source / note
A6: Unlevered free cash flow (lease payments deducted, so leases are excluded from the equity bridge)
A7: EBIT (operating profit) | H7: =IS!H11 -> 110738.72 | I7: =IS!I11 -> 111238.91 | J7: =IS!J11 -> 116351.91 | K7: =IS!K11 -> 121678.58 | L7: =IS!L11 -> 126076.68
A8: Taxes on EBIT | H8: =-H7*Assumptions!$G$70 -> -29899.455 | I8: =-I7*Assumptions!$G$70 -> -30034.505 | J8: =-J7*Assumptions!$G$70 -> -31415.017 | K8: =-K7*Assumptions!$G$70 -> -32853.217 | L8: =-L7*Assumptions!$G$70 -> -34040.704
A9: NOPAT | H9: =H7+H8 -> 80839.268 | I9: =I7+I8 -> 81204.403 | J9: =J7+J8 -> 84936.898 | K9: =K7+K8 -> 88825.363 | L9: =L7+L8 -> 92035.979
A10: + Depreciation ex right-of-use | H10: =CF!H8 -> 25860.231 | I10: =CF!I8 -> 26161.458 | J10: =CF!J8 -> 26333.904 | K10: =CF!K8 -> 26412.321 | L10: =CF!L8 -> 26561.122 | M10: ROU depreciation is not added back: it stands in for lease cost
A11: - Capex | H11: =CF!H19 -> -29099.226 | I11: =CF!I19 -> -28015.725 | J11: =CF!J19 -> -27177.09 | K11: =CF!K19 -> -28012.335 | L11: =CF!L19 -> -28817.528
A12: - Increase in net working capital | H12: =BS!G39-BS!H39 -> -8303.1595 | I12: =BS!H39-BS!I39 -> -243.70148 | J12: =BS!I39-BS!J39 -> -3226.5886 | K12: =BS!J39-BS!K39 -> -6114.4449 | L12: =BS!K39-BS!L39 -> -6891.7592
A13: Unlevered free cash flow | H13: =H9+H10+H11+H12 -> 69297.113 | I13: =I9+I10+I11+I12 -> 79106.434 | J13: =J9+J10+J11+J12 -> 80867.124 | K13: =K9+K10+K11+K12 -> 81110.904 | L13: =L9+L10+L11+L12 -> 82887.814
A14: Reinvestment (dep - capex - dNWC) % revenue | H14: =(H10+H11+H12)/IS!H5 -> -0.014279334 | I14: =(I10+I11+I12)/IS!I5 -> -0.0025461039 | J14: =(J10+J11+J12)/IS!J5 -> -0.0047920053 | K14: =(K10+K11+K12)/IS!K5 -> -0.0088126426 | L14: =(L10+L11+L12)/IS!L5 -> -0.010158445
A16: Timing
A17: Period start | H17: =Assumptions!$D$84+1 -> 46204 | I17: =DATE(2027,4,1) -> 46478 | J17: =DATE(2028,4,1) -> 46844 | K17: =DATE(2029,4,1) -> 47209 | L17: =DATE(2030,4,1) -> 47574
A18: Period end | H18: =DATE(2027,3,31) -> 46477 | I18: =DATE(2028,3,31) -> 46843 | J18: =DATE(2029,3,31) -> 47208 | K18: =DATE(2030,3,31) -> 47573 | L18: =DATE(2031,3,31) -> 47938
A19: Fraction of fiscal year included | H19: =(H18-H17+1)/(DATE(2027,3,31)-DATE(2026,3,31)) -> 0.75068493 | I19: =(I18-I17+1)/(DATE(2028,3,31)-DATE(2027,3,31)) -> 1 | J19: =(J18-J17+1)/(DATE(2029,3,31)-DATE(2028,3,31)) -> 1 | K19: =(K18-K17+1)/(DATE(2030,3,31)-DATE(2029,3,31)) -> 1 | L19: =(L18-L17+1)/(DATE(2031,3,31)-DATE(2030,3,31)) -> 1
A20: Years from valuation date to mid-period | H20: =((H17+H18)/2-Assumptions!$D$83)/365.25 -> 0.045174538 | I20: =((I17+I18)/2-Assumptions!$D$83)/365.25 -> 0.92128679 | J20: =((J17+J18)/2-Assumptions!$D$83)/365.25 -> 1.9219713 | K20: =((K17+K18)/2-Assumptions!$D$83)/365.25 -> 2.9212868 | L20: =((L17+L18)/2-Assumptions!$D$83)/365.25 -> 3.9206023
A21: UFCF included | H21: =H13*H19 -> 52020.298 | I21: =I13*I19 -> 79106.434 | J21: =J13*J19 -> 80867.124 | K21: =K13*K19 -> 81110.904 | L21: =L13*L19 -> 82887.814
A22: Discount factor | H22: =1/(1+Assumptions!$D$101)^H20 -> 0.99618172 | I22: =1/(1+Assumptions!$D$101)^I20 -> 0.92494693 | J22: =1/(1+Assumptions!$D$101)^J20 -> 0.84979376 | K22: =1/(1+Assumptions!$D$101)^K20 -> 0.7808374 | L22: =1/(1+Assumptions!$D$101)^L20 -> 0.71747649
A23: Present value | H23: =H21*H22 -> 51821.67 | I23: =I21*I22 -> 73169.254 | J23: =J21*J22 -> 68720.377 | K23: =K21*K22 -> 63334.427 | L23: =L21*L22 -> 59470.058
A24: Years of growth from FY2026 (for sensitivity) | H24: =1 -> 1 | I24: =2 -> 2 | J24: =3 -> 3 | K24: =4 -> 4 | L24: =5 -> 5
A26: Valuation summary
A27: WACC | D27: =Assumptions!$D$101 -> 0.088373867 | M27: Assumptions sheet
A28: Terminal growth | D28: =Assumptions!$G$78 -> 0.02
A29: Exit EV/EBITDA | D29: =Assumptions!$G$80 -> 7.5
A30: Years to end of FY2031 | D30: =($L$18-Assumptions!$D$83)/365.25 -> 4.4188912
A31: PV of explicit-period UFCF | D31: =SUM($H$23:$L$23) -> 316515.79
A32: + Cash + deposits + investments - borrowings - NCI - declared interim dividend | D32: =Assumptions!$D$102+Assumptions!$D$103+Assumptions!$D$104-Assumptions!$D$105-Assumptions!$D$106-Assumptions!$D$108*Assumptions!$D$86 -> 310456.21 | M32: 30 Jun 2026 balance sheet; investments at book; the stock is already ex the JPY 79 interim
A34: Gordon growth method
A35: RONIC (terminal) | D35: =Assumptions!$G$79 -> 0.12
A36: Terminal-year FCF: NOPAT FY2031 x (1 + g) x (1 - g / RONIC) | D36: =$L$9*(1+DCF!$D$28)*(1-DCF!$D$28/DCF!$D$35) -> 78230.582 | M36: Value-driver formula (McKinsey): avoids assuming FY2031's reinvestment rate forever
A37: Terminal value at end FY2031 | D37: =DCF!$D$36/(DCF!$D$27-DCF!$D$28) -> 1144159.1
A38: PV of terminal value | D38: =DCF!$D$37/(1+DCF!$D$27)^DCF!$D$30 -> 786987.74
A39: Enterprise value | D39: =DCF!$D$31+DCF!$D$38 -> 1103503.5
A40: Equity value | D40: =DCF!$D$39+DCF!$D$32 -> 1413959.7
A41: Value per share (JPY) | D41: =DCF!$D$40/Assumptions!$D$86 -> 5487.7916
A42: Terminal value share of EV | D42: =DCF!$D$38/DCF!$D$39 -> 0.71317193
A43: Implied exit EV/EBITDA (TV + leases) / EBITDA FY2031 | D43: =(DCF!$D$37+Assumptions!$D$107)/IS!$L$29 -> 7.3271094 | M43: Cross-check against the exit-multiple assumption
A45: Exit-multiple method
A46: Terminal value at end FY2031 (EBITDA x multiple - leases) | D46: =IS!$L$29*DCF!$D$29-Assumptions!$D$107 -> 1171607.5 | M46: Multiple applies to IFRS 16 EBITDA, which gives EV incl. leases; leases deducted for consistency
...

Sheet Comps
A1: Trading comparables
A2: Last reported fiscal year; all values converted to JPY m at 29 Oct 2026 FX (peers_financials.csv)
A4: Ticker | B4: Company | C4: FY end | D4: Mkt cap | E4: EV | F4: Revenue | G4: EBITDA | H4: Net income | I4: Equity | J4: EV/Sales | K4: EV/EBITDA | L4: P/E | M4: P/B | N4: EBITDA mgn
A5: 0669.HK | B5: Techtronic Industries | C5: 2025-12-31 | D5: 4807497.1 | E5: 4814893.4 | F5: 2408259.6 | G5: 326228.63 | H5: 189114.77 | I5: 1098183.3 | J5: =E5/F5 -> 1.9993249 | K5: =E5/G5 -> 14.759261 | L5: =D5/H5 -> 25.421056 | M5: =D5/I5 -> 4.377682 | N5: =G5/F5 -> 0.1354624
A6: SWK | B6: Stanley Black & Decker | C6: 2025-12-31 | D6: 2425172.4 | E6: 3327382 | F6: 2387879.8 | G6: 228302.42 | H6: 63427.861 | I6: 1428997 | J6: =E6/F6 -> 1.3934462 | K6: =E6/G6 -> 14.574449 | L6: =D6/H6 -> 38.235128 | M6: =D6/I6 -> 1.697115 | N6: =G6/F6 -> 0.09560884
A7: 2285.HK | B7: Chervon | C7: 2025-12-31 | D7: 340370.66 | E7: 324800.92 | F7: 256897.04 | G7: 27960.655 | H7: 15403.233 | I7: 160602.53 | J7: =E7/F7 -> 1.2643233 | K7: =E7/G7 -> 11.616356 | L7: =D7/H7 -> 22.097352 | M7: =D7/I7 -> 2.1193356 | N7: =G7/F7 -> 0.10883993
A8: HUSQ-B.ST | B8: Husqvarna | C8: 2025-12-31 | D8: 236614.52 | E8: 413090.63 | F8: 745994.44 | G8: 93639.402 | H8: 28295.071 | I8: 376686.14 | J8: =E8/F8 -> 0.55374492 | K8: =E8/G8 -> 4.4115043 | L8: =D8/H8 -> 8.3623935 | M8: =D8/I8 -> 0.62814767 | N8: =G8/F8 -> 0.12552292
A9: 6454.T | B9: Max Co. | C9: 2026-03-31 | D9: 328577.76 | E9: 286908.76 | F9: 99607 | G9: 21988 | H9: 13891 | I9: 115310 | J9: =E9/F9 -> 2.8804076 | K9: =E9/G9 -> 13.048425 | L9: =D9/H9 -> 23.654003 | M9: =D9/I9 -> 2.8495166 | N9: =G9/F9 -> 0.22074754
A10: 6250.T | B10: Yamabiko | C10: 2025-12-31 | D10: 178038.01 | E10: 177580.01 | F10: 174020 | G10: 24730 | H10: 14444 | I10: 119965 | J10: =E10/F10 -> 1.0204575 | K10: =E10/G10 -> 7.1807527 | L10: =D10/H10 -> 12.326088 | M10: =D10/I10 -> 1.484083 | N10: =G10/F10 -> 0.1421101
A11: TTC | B11: Toro | C11: 2025-10-31 | D11: 1574054.7 | E11: 1684544.5 | F11: 711831.36 | G11: 91472.476 | H11: 49886.904 | I11: 229359.82 | J11: =E11/F11 -> 2.3664938 | K11: =E11/G11 -> 18.415862 | L11: =D11/H11 -> 31.552463 | M11: =D11/I11 -> 6.8628181 | N11: =G11/F11 -> 0.12850302
B12: Median | J12: =MEDIAN(J5:J11) -> 1.3934462 | K12: =MEDIAN(K5:K11) -> 13.048425 | L12: =MEDIAN(L5:L11) -> 23.654003 | M12: =MEDIAN(M5:M11) -> 2.1193356 | N12: =MEDIAN(N5:N11) -> 0.12850302
B13: Mean | J13: =AVERAGE(J5:J11) -> 1.6397426 | K13: =AVERAGE(K5:K11) -> 12.000944 | L13: =AVERAGE(L5:L11) -> 23.092641 | M13: =AVERAGE(M5:M11) -> 2.859814 | N13: =AVERAGE(N5:N11) -> 0.13668496
B14: 25th percentile | J14: =QUARTILE(J5:J11,1) -> 1.1423904 | K14: =QUARTILE(K5:K11,1) -> 9.3985544 | L14: =QUARTILE(L5:L11,1) -> 17.21172 | M14: =QUARTILE(M5:M11,1) -> 1.590599 | N14: =QUARTILE(N5:N11,1) -> 0.11718142
B15: 75th percentile | J15: =QUARTILE(J5:J11,3) -> 2.1829093 | K15: =QUARTILE(K5:K11,3) -> 14.666855 | L15: =QUARTILE(L5:L11,3) -> 28.48676 | M15: =QUARTILE(M5:M11,3) -> 3.6135993 | N15: =QUARTILE(N5:N11,3) -> 0.13878625
A17: Makita (live, LTM to 30 Jun 2026)
B18: Market cap | D18: =Assumptions!$D$92 -> 1353464.4
B19: EV (incl. leases; cash + deposits deducted) | D19: =Assumptions!$D$92+Assumptions!$D$91-Assumptions!$D$102-Assumptions!$D$103+Assumptions!$D$106 -> 1098593.4 | F19: Same EV definition as peers (yfinance: total debt incl. leases less cash and short-term investments)
B20: Revenue LTM | D20: 797536 | F20: FY2026 + 1Q FY2027 - 1Q FY2026
B21: EBITDA LTM (IFRS 16) | D21: 140297
B22: Net income LTM | D22: 82999
B23: Parent equity 30 Jun 2026 | D23: 1006541
B24: EV/EBITDA | D24: =Comps!$D$19/Comps!$D$21 -> 7.8304839
B25: P/E | D25: =Comps!$D$18/Comps!$D$22 -> 16.306996
B26: EV/Sales | D26: =Comps!$D$19/Comps!$D$20 -> 1.3774844
B27: P/B | D27: =Comps!$D$18/Comps!$D$23 -> 1.3446689
B28: Makita own EV/EBITDA, FY2019-26 median | D28: 9.793065 | F28: makita_hist_multiples.csv
B29: Makita own EV/EBITDA, FY2019-26 low (ex FY2023 trough) | D29: 7.7718155
B30: Makita own EV/EBITDA, FY2019-26 high (ex FY2023 trough) | D30: 10.913784
A32: Implied Makita value per share (JPY)
B33: EV/EBITDA at peer median | D33: =(Comps!$K$12*Comps!$D$21-Comps!$D$19+Comps!$D$18)/Assumptions!$D$86 -> 8094.2412
B34: P/E at peer median | D34: =Comps!$L$12*Comps!$D$22/Assumptions!$D$86 -> 7619.7036
B35: EV/EBITDA at peer 25th percentile | D35: =(Comps!$K$14*Comps!$D$21-Comps!$D$19+Comps!$D$18)/Assumptions!$D$86 -> 6106.8361
B36: P/E at peer 25th percentile | D36: =Comps!$L$14*Comps!$D$22/Assumptions!$D$86 -> 5544.4401
B37: EV/EBITDA at peer 75th percentile | D37: =(Comps!$K$15*Comps!$D$21-Comps!$D$19+Comps!$D$18)/Assumptions!$D$86 -> 8975.4988
B38: P/E at peer 75th percentile | D38: =Comps!$L$15*Comps!$D$22/Assumptions!$D$86 -> 9176.4874
B39: EV/EBITDA at own FY2019-26 low | D39: =(Comps!$D$29*Comps!$D$21-Comps!$D$19+Comps!$D$18)/Assumptions!$D$86 -> 5221.0543
B40: EV/EBITDA at own FY2019-26 high | D40: =(Comps!$D$30*Comps!$D$21-Comps!$D$19+Comps!$D$18)/Assumptions!$D$86 -> 6931.8997
B41: EV/EBITDA at own FY2019-26 median | D41: =(Comps!$D$28*Comps!$D$21-Comps!$D$19+Comps!$D$18)/Assumptions!$D$86 -> 6321.6526
B43: Peer set: TTI, Stanley Black & Decker, Chervon (cordless power tools and OPE); Husqvarna, Toro, Yamabiko (OPE); Max (Japanese tools). Bosch and Hilti are private. SWK and Toro verified vs SEC 10-K.

Sheet Sensitivity
A1: Sensitivity tables (live formulas: each cell recomputes the DCF)
A2: Centre cells equal the DCF sheet; see Checks
A4: 1. Value per share (Gordon): WACC vs terminal growth
B5: WACC \ g | C5: =DCF!$D$28+(-0.01) -> 0.01 | D5: =DCF!$D$28+(-0.005) -> 0.015 | E5: =DCF!$D$28+(0) -> 0.02 | F5: =DCF!$D$28+(0.005) -> 0.025 | G5: =DCF!$D$28+(0.01) -> 0.03
B6: =DCF!$D$27+(-0.01) -> 0.078373867 | C6: =(SUMPRODUCT(DCF!$H$21:$L$21/(1+$B6)^DCF!$H$20:$L$20)+DCF!$L$9*(1+C$5)*(1-C$5/DCF!$D$35)/($B6-C$5)/(1+$B6)^DCF!$D$30+DCF!$D$32)/Assumptions!$D$86 -> 5921.3067 | D6: =(SUMPRODUCT(DCF!$H$21:$L$21/(1+$B6)^DCF!$H$20:$L$20)+DCF!$L$9*(1+D$5)*(1-D$5/DCF!$D$35)/($B6-D$5)/(1+$B6)^DCF!$D$30+DCF!$D$32)/Assumptions!$D$86 -> 6042.4386 | E6: =(SUMPRODUCT(DCF!$H$21:$L$21/(1+$B6)^DCF!$H$20:$L$20)+DCF!$L$9*(1+E$5)*(1-E$5/DCF!$D$35)/($B6-E$5)/(1+$B6)^DCF!$D$30+DCF!$D$32)/Assumptions!$D$86 -> 6182.4948 | F6: =(SUMPRODUCT(DCF!$H$21:$L$21/(1+$B6)^DCF!$H$20:$L$20)+DCF!$L$9*(1+F$5)*(1-F$5/DCF!$D$35)/($B6-F$5)/(1+$B6)^DCF!$D$30+DCF!$D$32)/Assumptions!$D$86 -> 6346.7937 | G6: =(SUMPRODUCT(DCF!$H$21:$L$21/(1+$B6)^DCF!$H$20:$L$20)+DCF!$L$9*(1+G$5)*(1-G$5/DCF!$D$35)/($B6-G$5)/(1+$B6)^DCF!$D$30+DCF!$D$32)/Assumptions!$D$86 -> 6542.8525
B7: =DCF!$D$27+(-0.005) -> 0.083373867 | C7: =(SUMPRODUCT(DCF!$H$21:$L$21/(1+$B7)^DCF!$H$20:$L$20)+DCF!$L$9*(1+C$5)*(1-C$5/DCF!$D$35)/($B7-C$5)/(1+$B7)^DCF!$D$30+DCF!$D$32)/Assumptions!$D$86 -> 5608.4636 | D7: =(SUMPRODUCT(DCF!$H$21:$L$21/(1+$B7)^DCF!$H$20:$L$20)+DCF!$L$9*(1+D$5)*(1-D$5/DCF!$D$35)/($B7-D$5)/(1+$B7)^DCF!$D$30+DCF!$D$32)/Assumptions!$D$86 -> 5701.5462 | E7: =(SUMPRODUCT(DCF!$H$21:$L$21/(1+$B7)^DCF!$H$20:$L$20)+DCF!$L$9*(1+E$5)*(1-E$5/DCF!$D$35)/($B7-E$5)/(1+$B7)^DCF!$D$30+DCF!$D$32)/Assumptions!$D$86 -> 5807.6681 | F7: =(SUMPRODUCT(DCF!$H$21:$L$21/(1+$B7)^DCF!$H$20:$L$20)+DCF!$L$9*(1+F$5)*(1-F$5/DCF!$D$35)/($B7-F$5)/(1+$B7)^DCF!$D$30+DCF!$D$32)/Assumptions!$D$86 -> 5930.1799 | G7: =(SUMPRODUCT(DCF!$H$21:$L$21/(1+$B7)^DCF!$H$20:$L$20)+DCF!$L$9*(1+G$5)*(1-G$5/DCF!$D$35)/($B7-G$5)/(1+$B7)^DCF!$D$30+DCF!$D$32)/Assumptions!$D$86 -> 6073.6877
B8: =DCF!$D$27+(0) -> 0.088373867 | C8: =(SUMPRODUCT(DCF!$H$21:$L$21/(1+$B8)^DCF!$H$20:$L$20)+DCF!$L$9*(1+C$5)*(1-C$5/DCF!$D$35)/($B8-C$5)/(1+$B8)^DCF!$D$30+DCF!$D$32)/Assumptions!$D$86 -> 5335.8 | D8: =(SUMPRODUCT(DCF!$H$21:$L$21/(1+$B8)^DCF!$H$20:$L$20)+DCF!$L$9*(1+D$5)*(1-D$5/DCF!$D$35)/($B8-D$5)/(1+$B8)^DCF!$D$30+DCF!$D$32)/Assumptions!$D$86 -> 5407.3148 | E8: =(SUMPRODUCT(DCF!$H$21:$L$21/(1+$B8)^DCF!$H$20:$L$20)+DCF!$L$9*(1+E$5)*(1-E$5/DCF!$D$35)/($B8-E$5)/(1+$B8)^DCF!$D$30+DCF!$D$32)/Assumptions!$D$86 -> 5487.7916 | F8: =(SUMPRODUCT(DCF!$H$21:$L$21/(1+$B8)^DCF!$H$20:$L$20)+DCF!$L$9*(1+F$5)*(1-F$5/DCF!$D$35)/($B8-F$5)/(1+$B8)^DCF!$D$30+DCF!$D$32)/Assumptions!$D$86 -> 5579.3518 | G8: =(SUMPRODUCT(DCF!$H$21:$L$21/(1+$B8)^DCF!$H$20:$L$20)+DCF!$L$9*(1+G$5)*(1-G$5/DCF!$D$35)/($B8-G$5)/(1+$B8)^DCF!$D$30+DCF!$D$32)/Assumptions!$D$86 -> 5684.8433
B9: =DCF!$D$27+(0.005) -> 0.093373867 | C9: =(SUMPRODUCT(DCF!$H$21:$L$21/(1+$B9)^DCF!$H$20:$L$20)+DCF!$L$9*(1+C$5)*(1-C$5/DCF!$D$35)/($B9-C$5)/(1+$B9)^DCF!$D$30+DCF!$D$32)/Assumptions!$D$86 -> 5096.0772 | D9: =(SUMPRODUCT(DCF!$H$21:$L$21/(1+$B9)^DCF!$H$20:$L$20)+DCF!$L$9*(1+D$5)*(1-D$5/DCF!$D$35)/($B9-D$5)/(1+$B9)^DCF!$D$30+DCF!$D$32)/Assumptions!$D$86 -> 5150.8052 | E9: =(SUMPRODUCT(DCF!$H$21:$L$21/(1+$B9)^DCF!$H$20:$L$20)+DCF!$L$9*(1+E$5)*(1-E$5/DCF!$D$35)/($B9-E$5)/(1+$B9)^DCF!$D$30+DCF!$D$32)/Assumptions!$D$86 -> 5211.6248 | F9: =(SUMPRODUCT(DCF!$H$21:$L$21/(1+$B9)^DCF!$H$20:$L$20)+DCF!$L$9*(1+F$5)*(1-F$5/DCF!$D$35)/($B9-F$5)/(1+$B9)^DCF!$D$30+DCF!$D$32)/Assumptions!$D$86 -> 5279.8723 | G9: =(SUMPRODUCT(DCF!$H$21:$L$21/(1+$B9)^DCF!$H$20:$L$20)+DCF!$L$9*(1+G$5)*(1-G$5/DCF!$D$35)/($B9-G$5)/(1+$B9)^DCF!$D$30+DCF!$D$32)/Assumptions!$D$86 -> 5357.3057
B10: =DCF!$D$27+(0.01) -> 0.098373867 | C10: =(SUMPRODUCT(DCF!$H$21:$L$21/(1+$B10)^DCF!$H$20:$L$20)+DCF!$L$9*(1+C$5)*(1-C$5/DCF!$D$35)/($B10-C$5)/(1+$B10)^DCF!$D$30+DCF!$D$32)/Assumptions!$D$86 -> 4883.6949 | D10: =(SUMPRODUCT(DCF!$H$21:$L$21/(1+$B10)^DCF!$H$20:$L$20)+DCF!$L$9*(1+D$5)*(1-D$5/DCF!$D$35)/($B10-D$5)/(1+$B10)^DCF!$D$30+DCF!$D$32)/Assumptions!$D$86 -> 4925.2233 | E10: =(SUMPRODUCT(DCF!$H$21:$L$21/(1+$B10)^DCF!$H$20:$L$20)+DCF!$L$9*(1+E$5)*(1-E$5/DCF!$D$35)/($B10-E$5)/(1+$B10)^DCF!$D$30+DCF!$D$32)/Assumptions!$D$86 -> 4970.796 | F10: =(SUMPRODUCT(DCF!$H$21:$L$21/(1+$B10)^DCF!$H$20:$L$20)+DCF!$L$9*(1+F$5)*(1-F$5/DCF!$D$35)/($B10-F$5)/(1+$B10)^DCF!$D$30+DCF!$D$32)/Assumptions!$D$86 -> 5021.2397 | G10: =(SUMPRODUCT(DCF!$H$21:$L$21/(1+$B10)^DCF!$H$20:$L$20)+DCF!$L$9*(1+G$5)*(1-G$5/DCF!$D$35)/($B10-G$5)/(1+$B10)^DCF!$D$30+DCF!$D$32)/Assumptions!$D$86 -> 5077.6231
A12: 2. Value per share (exit multiple): WACC vs exit EV/EBITDA
B13: WACC \ Multiple | C13: =DCF!$D$29+(-2) -> 5.5 | D13: =DCF!$D$29+(-1) -> 6.5 | E13: =DCF!$D$29+(0) -> 7.5 | F13: =DCF!$D$29+(1) -> 8.5 | G13: =DCF!$D$29+(2) -> 9.5
B14: =DCF!$D$27+(-0.01) -> 0.078373867 | C14: =(SUMPRODUCT(DCF!$H$21:$L$21/(1+$B14)^DCF!$H$20:$L$20)+(IS!$L$29*C$13-Assumptions!$D$107)/(1+$B14)^DCF!$D$30+DCF!$D$32)/Assumptions!$D$86 -> 4830.8451 | D14: =(SUMPRODUCT(DCF!$H$21:$L$21/(1+$B14)^DCF!$H$20:$L$20)+(IS!$L$29*D$13-Assumptions!$D$107)/(1+$B14)^DCF!$D$30+DCF!$D$32)/Assumptions!$D$86 -> 5272.3156 | E14: =(SUMPRODUCT(DCF!$H$21:$L$21/(1+$B14)^DCF!$H$20:$L$20)+(IS!$L$29*E$13-Assumptions!$D$107)/(1+$B14)^DCF!$D$30+DCF!$D$32)/Assumptions!$D$86 -> 5713.786 | F14: =(SUMPRODUCT(DCF!$H$21:$L$21/(1+$B14)^DCF!$H$20:$L$20)+(IS!$L$29*F$13-Assumptions!$D$107)/(1+$B14)^DCF!$D$30+DCF!$D$32)/Assumptions!$D$86 -> 6155.2564 | G14: =(SUMPRODUCT(DCF!$H$21:$L$21/(1+$B14)^DCF!$H$20:$L$20)+(IS!$L$29*G$13-Assumptions!$D$107)/(1+$B14)^DCF!$D$30+DCF!$D$32)/Assumptions!$D$86 -> 6596.7269
B15: =DCF!$D$27+(-0.005) -> 0.083373867 | C15: =(SUMPRODUCT(DCF!$H$21:$L$21/(1+$B15)^DCF!$H$20:$L$20)+(IS!$L$29*C$13-Assumptions!$D$107)/(1+$B15)^DCF!$D$30+DCF!$D$32)/Assumptions!$D$86 -> 4771.4366 | D15: =(SUMPRODUCT(DCF!$H$21:$L$21/(1+$B15)^DCF!$H$20:$L$20)+(IS!$L$29*D$13-Assumptions!$D$107)/(1+$B15)^DCF!$D$30+DCF!$D$32)/Assumptions!$D$86 -> 5203.9744 | E15: =(SUMPRODUCT(DCF!$H$21:$L$21/(1+$B15)^DCF!$H$20:$L$20)+(IS!$L$29*E$13-Assumptions!$D$107)/(1+$B15)^DCF!$D$30+DCF!$D$32)/Assumptions!$D$86 -> 5636.5122 | F15: =(SUMPRODUCT(DCF!$H$21:$L$21/(1+$B15)^DCF!$H$20:$L$20)+(IS!$L$29*F$13-Assumptions!$D$107)/(1+$B15)^DCF!$D$30+DCF!$D$32)/Assumptions!$D$86 -> 6069.05 | G15: =(SUMPRODUCT(DCF!$H$21:$L$21/(1+$B15)^DCF!$H$20:$L$20)+(IS!$L$29*G$13-Assumptions!$D$107)/(1+$B15)^DCF!$D$30+DCF!$D$32)/Assumptions!$D$86 -> 6501.5878
B16: =DCF!$D$27+(0) -> 0.088373867 | C16: =(SUMPRODUCT(DCF!$H$21:$L$21/(1+$B16)^DCF!$H$20:$L$20)+(IS!$L$29*C$13-Assumptions!$D$107)/(1+$B16)^DCF!$D$30+DCF!$D$32)/Assumptions!$D$86 -> 4713.4155 | D16: =(SUMPRODUCT(DCF!$H$21:$L$21/(1+$B16)^DCF!$H$20:$L$20)+(IS!$L$29*D$13-Assumptions!$D$107)/(1+$B16)^DCF!$D$30+DCF!$D$32)/Assumptions!$D$86 -> 5137.2413 | E16: =(SUMPRODUCT(DCF!$H$21:$L$21/(1+$B16)^DCF!$H$20:$L$20)+(IS!$L$29*E$13-Assumptions!$D$107)/(1+$B16)^DCF!$D$30+DCF!$D$32)/Assumptions!$D$86 -> 5561.0671 | F16: =(SUMPRODUCT(DCF!$H$21:$L$21/(1+$B16)^DCF!$H$20:$L$20)+(IS!$L$29*F$13-Assumptions!$D$107)/(1+$B16)^DCF!$D$30+DCF!$D$32)/Assumptions!$D$86 -> 5984.8929 | G16: =(SUMPRODUCT(DCF!$H$21:$L$21/(1+$B16)^DCF!$H$20:$L$20)+(IS!$L$29*G$13-Assumptions!$D$107)/(1+$B16)^DCF!$D$30+DCF!$D$32)/Assumptions!$D$86 -> 6408.7187
B17: =DCF!$D$27+(0.005) -> 0.093373867 | C17: =(SUMPRODUCT(DCF!$H$21:$L$21/(1+$B17)^DCF!$H$20:$L$20)+(IS!$L$29*C$13-Assumptions!$D$107)/(1+$B17)^DCF!$D$30+DCF!$D$32)/Assumptions!$D$86 -> 4656.7426 | D17: =(SUMPRODUCT(DCF!$H$21:$L$21/(1+$B17)^DCF!$H$20:$L$20)+(IS!$L$29*D$13-Assumptions!$D$107)/(1+$B17)^DCF!$D$30+DCF!$D$32)/Assumptions!$D$86 -> 5072.0706 | E17: =(SUMPRODUCT(DCF!$H$21:$L$21/(1+$B17)^DCF!$H$20:$L$20)+(IS!$L$29*E$13-Assumptions!$D$107)/(1+$B17)^DCF!$D$30+DCF!$D$32)/Assumptions!$D$86 -> 5487.3986 | F17: =(SUMPRODUCT(DCF!$H$21:$L$21/(1+$B17)^DCF!$H$20:$L$20)+(IS!$L$29*F$13-Assumptions!$D$107)/(1+$B17)^DCF!$D$30+DCF!$D$32)/Assumptions!$D$86 -> 5902.7266 | G17: =(SUMPRODUCT(DCF!$H$21:$L$21/(1+$B17)^DCF!$H$20:$L$20)+(IS!$L$29*G$13-Assumptions!$D$107)/(1+$B17)^DCF!$D$30+DCF!$D$32)/Assumptions!$D$86 -> 6318.0546
B18: =DCF!$D$27+(0.01) -> 0.098373867 | C18: =(SUMPRODUCT(DCF!$H$21:$L$21/(1+$B18)^DCF!$H$20:$L$20)+(IS!$L$29*C$13-Assumptions!$D$107)/(1+$B18)^DCF!$D$30+DCF!$D$32)/Assumptions!$D$86 -> 4601.3799 | D18: =(SUMPRODUCT(DCF!$H$21:$L$21/(1+$B18)^DCF!$H$20:$L$20)+(IS!$L$29*D$13-Assumptions!$D$107)/(1+$B18)^DCF!$D$30+DCF!$D$32)/Assumptions!$D$86 -> 5008.4181 | E18: =(SUMPRODUCT(DCF!$H$21:$L$21/(1+$B18)^DCF!$H$20:$L$20)+(IS!$L$29*E$13-Assumptions!$D$107)/(1+$B18)^DCF!$D$30+DCF!$D$32)/Assumptions!$D$86 -> 5415.4563 | F18: =(SUMPRODUCT(DCF!$H$21:$L$21/(1+$B18)^DCF!$H$20:$L$20)+(IS!$L$29*F$13-Assumptions!$D$107)/(1+$B18)^DCF!$D$30+DCF!$D$32)/Assumptions!$D$86 -> 5822.4945 | G18: =(SUMPRODUCT(DCF!$H$21:$L$21/(1+$B18)^DCF!$H$20:$L$20)+(IS!$L$29*G$13-Assumptions!$D$107)/(1+$B18)^DCF!$D$30+DCF!$D$32)/Assumptions!$D$86 -> 6229.5327
A20: 3. Value per share (Gordon): annual revenue growth uplift vs steady-state operating margin
B21: Growth +/- \ OP margin | C21: =0.11 -> 0.11 | D21: =0.125 -> 0.125 | E21: =0.14 -> 0.14 | F21: =0.155 -> 0.155 | G21: =0.17 -> 0.17
